Workbook

Sheet Tarkib
B2: Yo'q | C2: Jadval nomlari
B3: 1 | C3: 2025-йил учун мақсадли ва амалдаги кўрсаткичлар
B4: 2 | C4: IT-Park резидентлари фаолиятининг асосий кўрсаткичлари
B5: 3 | C5: IT-Parkнинг экспорт кўрсаткичлари ва тузилиши
B6: 3.1 | C6: Мамлакатлар бўйича IT хизматлари экспорти
B7: 3.2 | C7: IT-Park резидентлари орасидаги ТОП-10 экспортчилар
B8: 3.3 | C8: Экспорт хажмини оширган IT-Park резидентлари
B9: 3.4 | C9: Экспорт хажмини камайтирган IT-Park резидентлари
B10: 4 | C10: IT-Park резидентлари томонидан кўрсатилган хизматлар ҳажми
B11: 5 | C11: 2025 йилларга мўлжалланган инвестицияларни ўзлаштириш кўрсаткичлари
B12: 6 | C12: 2025-йил учун вилоятлар кесимида маълумот
B13: 6.1 | C13: Расмий статистика - АКТ хизматлар ҳажм (Миллий статистика қўмитаси маълумотлари)
B14: 7 | C14: IT Park резидентлари тўғрисида маълумот
B15: 7.1 | C15: IT-park резидентлари регистри, (01.01.2026 йил, мамлакатлар кесимида)
B16: 8 | C16: Тақдим этилган хизматлар хақида маълумот (Ягона дарча /OSS/)
B17: 8.1 | C17: 2025 йил учун мамлакатлар кесимида Ягона дарча (One Stop Shop / OSS) орқали кўрсатилган хизматлар тўғрисида маълумот
B18: 9 | C18: IT Visa дастури бўйича берилган ID Cardлар тўғрисида маълумот
B19: 9.1 | C19: Мамлакатлар кесимида берилган ID-карталар хақида маълумот
B20: 10 | C20: IT Park хорижий резидентлари (асосий кўрсаткичлар)
B21: 11 | C21: Халқаро ҳамкорликлар ва IT-Park тадбирлари

Sheet 1-жадвал
T1: 1-жадвал
A2: 2026-йил учун мақсадли ва амалдаги кўрсаткичлар
A4: № | B4: Мақсадлар номи | C4: Ўлчов бирлиги | D4: ='2-жадвал'!D5 -> 2025-йил | E4: Январ-март | I4: Январ-июнь | M4: Январ-сентябрь | Q4: Январ-декабрь
E5: Амалда | F5: (KPI) | G5: Фарқи + / - | H5: Бажарилиш, % да | I5: Амалда | J5: (KPI) | K5: Фарқи + / - | L5: Бажарилиш, % да | M5: Амалда | N5: (KPI) | O5: Фарқи + / - | P5: Бажарилиш, % да | Q5: Амалда | R5: (KPI) | S5: Фарқи + / - | T5: Бажарилиш, % да
A6: Rezident
A7: 1 | B7: ИТ Парк резидентлари | C7: миқдор | D7: 3435 | F7: 3500 | G7: =E7-F7 -> -3500 | H7: =IFERROR(E7/F7, "-") -> 0 | J7: 3800 | K7: =I7-J7 -> -3800 | L7: =IFERROR(I7/J7, "-") -> 0 | N7: 4200 | O7: =M7-N7 -> -4200 | P7: =IFERROR(M7/N7, "-") -> 0 | R7: 4500 | S7: =Q7-R7 -> -4500 | T7: =IFERROR(Q7/R7, "-") -> 0
A8: 1.1 | B8: шундан худудларда | C8: миқдор | D8: 1308 | F8: 1400 | G8: =E8-F8 -> -1400 | H8: =IFERROR(E8/F8, "-") -> 0 | J8: 1550 | K8: =I8-J8 -> -1550 | L8: =IFERROR(I8/J8, "-") -> 0 | N8: 1650 | O8: =M8-N8 -> -1650 | P8: =IFERROR(M8/N8, "-") -> 0 | R8: 1800 | S8: =Q8-R8 -> -1800 | T8: =IFERROR(Q8/R8, "-") -> 0
A9: 2 | B9: ИТ Паркнинг хорижий резидентлари | C9: миқдор | D9: 972 | F9: 1000 | G9: =E9-F9 -> -1000 | H9: =IFERROR(E9/F9, "-") -> 0 | J9: 1100 | K9: =I9-J9 -> -1100 | L9: =IFERROR(I9/J9, "-") -> 0 | N9: 1150 | O9: =M9-N9 -> -1150 | P9: =IFERROR(M9/N9, "-") -> 0 | R9: 1250 | S9: =Q9-R9 -> -1250 | T9: =IFERROR(Q9/R9, "-") -> 0
A10: 2.1 | B10: шундан худудларда | C10: миқдор | D10: 309 | F10: 320 | G10: =E10-F10 -> -320 | H10: =IFERROR(E10/F10, "-") -> 0 | J10: 340 | K10: =I10-J10 -> -340 | L10: =IFERROR(I10/J10, "-") -> 0 | N10: 360 | O10: =M10-N10 -> -360 | P10: =IFERROR(M10/N10, "-") -> 0 | R10: 380 | S10: =Q10-R10 -> -380 | T10: =IFERROR(Q10/R10, "-") -> 0
A11: 3 | B11: Экспортчи резидентлар жами | C11: миқдор | D11: 900 | F11: 920 | G11: =E11-F11 -> -920 | H11: =IFERROR(E11/F11, "-") -> 0 | J11: 950 | K11: =I11-J11 -> -950 | L11: =IFERROR(I11/J11, "-") -> 0 | N11: 1000 | O11: =M11-N11 -> -1000 | P11: =IFERROR(M11/N11, "-") -> 0 | R11: 1050 | S11: =Q11-R11 -> -1050 | T11: =IFERROR(Q11/R11, "-") -> 0
A12: 3.1 | B12: шундан худудларда | C12: миқдор | D12: 281 | F12: 290 | G12: =E12-F12 -> -290 | H12: =IFERROR(E12/F12, "-") -> 0 | J12: 300 | K12: =I12-J12 -> -300 | L12: =IFERROR(I12/J12, "-") -> 0 | N12: 320 | O12: =M12-N12 -> -320 | P12: =IFERROR(M12/N12, "-") -> 0 | R12: 350 | S12: =Q12-R12 -> -350 | T12: =IFERROR(Q12/R12, "-") -> 0
A13: 4 | B13: Экспортчи резидентлар (экспорт 50% дан юқори) | C13: миқдор | G13: =E13-F13 -> 0 | H13: =IFERROR(E13/F13, "-") -> - | K13: =I13-J13 -> 0 | L13: =IFERROR(I13/J13, "-") -> - | O13: =M13-N13 -> 0 | P13: =IFERROR(M13/N13, "-") -> - | S13: =Q13-R13 -> 0 | T13: =IFERROR(Q13/R13, "-") -> -
A14: 4.1 | B14: шундан худудларда | C14: миқдор | G14: =E14-F14 -> 0 | H14: =IFERROR(E14/F14, "-") -> - | K14: =I14-J14 -> 0 | L14: =IFERROR(I14/J14, "-") -> - | O14: =M14-N14 -> 0 | P14: =IFERROR(M14/N14, "-") -> - | S14: =Q14-R14 -> 0 | T14: =IFERROR(Q14/R14, "-") -> -
A15: 5 | B15: Резидентлар томонидан кўрсатилган хизматлар хажми | C15: трлн. сўм | D15: 33.4 | F15: 8.5 | G15: =E15-F15 -> -8.5 | H15: =IFERROR(E15/F15, "-") -> 0 | J15: 17 | K15: =I15-J15 -> -17 | L15: =IFERROR(I15/J15, "-") -> 0 | N15: 25 | O15: =M15-N15 -> -25 | P15: =IFERROR(M15/N15, "-") -> 0 | R15: 33.4 | S15: =Q15-R15 -> -33.4 | T15: =IFERROR(Q15/R15, "-") -> 0
A16: 5.1 | B16: шундан худудларда | C16: трлн. сўм | G16: =E16-F16 -> 0 | H16: =IFERROR(E16/F16, "-") -> - | K16: =I16-J16 -> 0 | L16: =IFERROR(I16/J16, "-") -> - | O16: =M16-N16 -> 0 | P16: =IFERROR(M16/N16, "-") -> - | S16: =Q16-R16 -> 0 | T16: =IFERROR(Q16/R16, "-") -> -
A17: 6 | B17: Резидентлар томонидан ИТ хизматларини експорт қилиш | C17: млн. АҚШ доллар | G17: =E17-F17 -> 0 | H17: =IFERROR(E17/F17, "-") -> - | K17: =I17-J17 -> 0 | L17: =IFERROR(I17/J17, "-") -> - | O17: =M17-N17 -> 0 | P17: =IFERROR(M17/N17, "-") -> - | S17: =Q17-R17 -> 0 | T17: =IFERROR(Q17/R17, "-") -> -
A18: 6.1 | B18: шундан худудларда | C18: млн. АҚШ доллар | G18: =E18-F18 -> 0 | H18: =IFERROR(E18/F18, "-") -> - | K18: =I18-J18 -> 0 | L18: =IFERROR(I18/J18, "-") -> - | O18: =M18-N18 -> 0 | P18: =IFERROR(M18/N18, "-") -> - | S18: =Q18-R18 -> 0 | T18: =IFERROR(Q18/R18, "-") -> -
A19: Startap
A20: 7 | B20: Дастурда иштирокчилар сони "Рақамли стартаплар» | C20: миқдор | D20: 21 | F20: 31 | G20: =E20-F20 -> -31 | H20: =IFERROR(E20/F20, "-") -> 0 | J20: 52 | K20: =I20-J20 -> -52 | L20: =IFERROR(I20/J20, "-") -> 0 | N20: 92 | O20: =M20-N20 -> -92 | P20: =IFERROR(M20/N20, "-") -> 0 | R20: 152 | S20: =Q20-R20 -> -152 | T20: =IFERROR(Q20/R20, "-") -> 0
A21: 8 | B21: Стартапларни қўллаб-қувватлаш учун ажратилган маблағлар миқдори (аниқлик киритиш керак) | C21: минг АҚШ доллар | D21: 1340.23 | F21: 2500 | G21: =E21-F21 -> -2500 | H21: =IFERROR(E21/F21, "-") -> 0 | J21: 5000 | K21: =I21-J21 -> -5000 | L21: =IFERROR(I21/J21, "-") -> 0 | N21: 7500 | O21: =M21-N21 -> -7500 | P21: =IFERROR(M21/N21, "-") -> 0 | R21: 11000 | S21: =Q21-R21 -> -11000 | T21: =IFERROR(Q21/R21, "-") -> 0
A22: 10 | B22: Стартапларга инвеститсиялар хажми (махаллий) | C22: минг АҚШ доллар | D22: 40006 | F22: 8000 | G22: =E22-F22 -> -8000 | H22: =IFERROR(E22/F22, "-") -> 0 | J22: 13000 | K22: =I22-J22 -> -13000 | L22: =IFERROR(I22/J22, "-") -> 0 | N22: 25000 | O22: =M22-N22 -> -25000 | P22: =IFERROR(M22/N22, "-") -> 0 | R22: 40000 | S22: =Q22-R22 -> -40000 | T22: =IFERROR(Q22/R22, "-") -> 0
A23: 9 | B23: Венчур молиялаштириш орқали стартап лойихаларига инвеститсияларни жалб қилиш (халқаро) | C23: минг АҚШ доллар | D23: 97098 | F23: 8000 | G23: =E23-F23 -> -8000 | H23: =IFERROR(E23/F23, "-") -> 0 | J23: 13000 | K23: =I23-J23 -> -13000 | L23: =IFERROR(I23/J23, "-") -> 0 | N23: 18000 | O23: =M23-N23 -> -18000 | P23: =IFERROR(M23/N23, "-") -> 0 | R23: 25000 | S23: =Q23-R23 -> -25000 | T23: =IFERROR(Q23/R23, "-") -> 0
A24: 11 | B24: Махаллий стартап-екотизимининг ягона платформасида (startupbase.uz) ро‘йхатдан о‘тган махаллий стартаплар улушини хар йили о‘тказиладиган инкубатсия ва акселератсия дастурлари доирасида камида 10 фоиз даражада та’минлаш | C24: % | D24: 5 | F24: 10 | G24: =E24-F24 -> -10 | H24: =IFERROR(E24/F24, "-") -> 0 | J24: 10 | K24: =I24-J24 -> -10 | L24: =IFERROR(I24/J24, "-") -> 0 | N24: 10 | O24: =M24-N24 -> -10 | P24: =IFERROR(M24/N24, "-") -> 0 | R24: 10 | S24: =Q24-R24 -> -10 | T24: =IFERROR(Q24/R24, "-") -> 0
A25: 12 | B25: Бозор капиталлашуви 50 миллион АҚШ доллардан ортиқ бо‘лган стартапларни яратиш | C25: миқдор | D25: 5 | F25: 6 | G25: =E25-F25 -> -6 | H25: =IFERROR(E25/F25, "-") -> 0 | J25: 6 | K25: =I25-J25 -> -6 | L25: =IFERROR(I25/J25, "-") -> 0 | N25: 7 | O25: =M25-N25 -> -7 | P25: =IFERROR(M25/N25, "-") -> 0 | R25: 7 | S25: =Q25-R25 -> -7 | T25: =IFERROR(Q25/R25, "-") -> 0
A26: 13 | B26: Бозор капиталлашуви 5 миллион АҚШ доллардан ортиқ бо‘лган стартапларни яратиш | C26: миқдор | D26: 22 | F26: 25 | G26: =E26-F26 -> -25 | H26: =IFERROR(E26/F26, "-") -> 0 | J26: 35 | K26: =I26-J26 -> -35 | L26: =IFERROR(I26/J26, "-") -> 0 | N26: 50 | O26: =M26-N26 -> -50 | P26: =IFERROR(M26/N26, "-") -> 0 | R26: 75 | S26: =Q26-R26 -> -75 | T26: =IFERROR(Q26/R26, "-") -> 0
A27: 14 | B27: ИТ Парк Узбекистан инкубатсия ва акселератсия дастурларига киритилган стартап-лойихалар сонини 2 мингтага йетказиш | C27: миқдор | D27: 1251 | F27: 900 | G27: =E27-F27 -> -900 | H27: =IFERROR(E27/F27, "-") -> 0 | J27: 920 | K27: =I27-J27 -> -920 | L27: =IFERROR(I27/J27, "-") -> 0 | N27: 940 | O27: =M27-N27 -> -940 | P27: =IFERROR(M27/N27, "-") -> 0 | R27: 1000 | S27: =Q27-R27 -> -1000 | T27: =IFERROR(Q27/R27, "-") -> 0
A28: 15 | B28: Жахон стартап-екотизими индекси (Global Startup Ecosystem Index) | C28: ўрни | D28: 98 | F28: 0 | G28: =E28-F28 -> 0 | H28: =IFERROR(E28/F28, "-") -> - | J28: 0 | K28: =I28-J28 -> 0 | L28: =IFERROR(I28/J28, "-") -> - | N28: 0 | O28: =M28-N28 -> 0 | P28: =IFERROR(M28/N28, "-") -> - | R28: 90 | S28: =Q28-R28 -> -90 | T28: =IFERROR(Q28/R28, "-") -> 0
A29: 15.1 | B29: рейтингдаги ўзгариш | C29: миқдор | F29: 0 | G29: =E29-F29 -> 0 | H29: =IFERROR(E29/F29, "-") -> - | J29: 0 | K29: =I29-J29 -> 0 | L29: =IFERROR(I29/J29, "-") -> - | N29: 0 | O29: =M29-N29 -> 0 | P29: =IFERROR(M29/N29, "-") -> - | R29: 8 | S29: =Q29-R29 -> -8 | T29: =IFERROR(Q29/R29, "-") -> 0
A30: 6 | B30: Қурилиб, фойдаланишга топшириладиган ИТ-паркларнинг тўлақонли минтақавий филиаллари сони | C30: миқдор | D30: 2 | F30: 2 | G30: =E30-F30 -> -2 | H30: =IFERROR(E30/F30, "-") -> 0 | J30: 3 | K30: =I30-J30 -> -3 | L30: =IFERROR(I30/J30, "-") -> 0 | N30: 4 | O30: =M30-N30 -> -4 | P30: =IFERROR(M30/N30, "-") -> 0 | R30: 5 | S30: =Q30-R30 -> -5 | T30: =IFERROR(Q30/R30, "-") -> 0

Sheet 2-жадвал
F1: 2-жадвал
A3: IT-Park резидентлари фаолиятининг асосий кўрсаткичлари
A5: № | B5: Кўрсаткич номи | C5: 2024-йил | D5: 2025-йил | E5: Улуши | F5: Ўсиш суръати
A7: 1 | B7: Жами даромад хажми (умумий), млрд. сўм; АКТ сохасида IT-Park резидентларининг республикадаги улуши (%) | C7: =C9+C10 -> 20423 | D7: =D9+D10 -> 33405 | E7: 0.42 | F7: =IFERROR(D7/C7, "-") -> 1.6356559
B8: шундан:
A9: 1.1 | B9: ички бозор, млрд. сўм | C9: 14547 | D9: 24594 | E9: =D9/$D$7 -> 0.73623709 | F9: =IFERROR(D9/C9, "-") -> 1.6906579
A10: 1.2 | B10: экспортдан, млрд. сўм | C10: 5876 | D10: 8811 | E10: =D10/$D$7 -> 0.26376291 | F10: =IFERROR(D10/C10, "-") -> 1.4994894
A11: 2 | B11: Экспорт хизматлар, млн. АҚШ доллари | C11: 466.4 | D11: 716.4 | E11: х | F11: =IFERROR(D11/C11, "-") -> 1.5360206
A12: 3 | B12: Инвестициялар, млн. АҚШ доллари | D12: 164.6 | E12: х | F12: =IFERROR(D12/C12, "-") -> -
A13: 3.1 | B13: шу жумладан, тўғридан-тўғри хорижий инвеститсиялар | D13: 86.7 | E13: =D13/D12 -> 0.52673147 | F13: =IFERROR(D13/C13, "-") -> -
A14: 4 | B14: Резидентлар сони | C14: 2600 | D14: 3435 | E14: 1 | F14: =IFERROR(D14/C14, "-") -> 1.3211538
A15: 4.1 | B15: шу жумладан хорижий | C15: 642 | D15: 972 | E15: =D15/D14 -> 0.28296943 | F15: =IFERROR(D15/C15, "-") -> 1.5140187
A16: 5 | B16: Фаолиятини давом эттирайётган резидентлар | C16: 2017 | D16: 3435 | E16: х | F16: =IFERROR(D16/C16, "-") -> 1.7030243
A17: 5.1 | B17: Фаолиятини 1 йилгача давом эттирайётганлар | C17: 715 | D17: 919 | E17: =D17/$D$16 -> 0.26754003 | F17: =IFERROR(D17/C17, "-") -> 1.2853147
A18: 5.2 | B18: Фаолиятини 3 йилдан ортиқ давом эттирайётганлар | C18: 723 | D18: 1349 | E18: =D18/$D$16 -> 0.39272198 | F18: =IFERROR(D18/C18, "-") -> 1.8658368
A19: 6 | B19: Резидентларда ходимлари сони | C19: 38651 | D19: 53026 | E19: х | F19: =IFERROR(D19/C19, "-") -> 1.3719179

Sheet 3-жадвал
F1: 3-жадвал
A3: IT-Parkнинг экспорт кўрсаткичлари ва тузилиши
F4: млн. АҚШ долл.
A5: № | B5: Кўрсаткич номи | C5: ='2-жадвал'!C5 -> 2024-йил | D5: ='2-жадвал'!D5 -> 2025-йил | E5: Улуши | F5: Ўсиш суръати
B7: АКТ сохасидаги жами экспорт | D7: 1200 | E7: 100 | F7: =IFERROR(D7/C7, "-") -> -
A8: -- | B8: кутилайотган ко‘рсаткичлар | D8: 1020 | E8: х | F8: х
A9: -- | B9: фарқ (+/-) | C9: =C7-C8 -> 0 | D9: =D7-D8 -> 180 | E9: х | F9: х
A10: 1 | B10: IT-Park резидентларининг экспорти | C10: 466.4 | D10: 716.4 | E10: =E12+E13+E14+E15+E16 -> 1 | F10: =IFERROR(D10/C10, "-") -> 1.5360206
B11: шу жумладан хорижий резидентларнинг экспорти | C11: 275.2 | D11: 411 | E11: =D11/D10 -> 0.57370184 | F11: =IFERROR(D11/C11, "-") -> 1.4934593
A12: 1.1 | B12: BPO / autsorsing | C12: 254.8 | D12: 319.3 | E12: =D12/$D$10 -> 0.44570073 | F12: =IFERROR(D12/C12, "-") -> 1.2531397
A13: 1.2 | B13: HQ | C13: 19.4 | D13: 46.1 | E13: =D13/$D$10 -> 0.064349525 | F13: =IFERROR(D13/C13, "-") -> 2.3762887
A14: 1.3 | B14: IT ўкитиш | C14: 104.1 | D14: 179.7 | E14: =D14/$D$10 -> 0.25083752 | F14: =IFERROR(D14/C14, "-") -> 1.7262248
A15: 1.4 | B15: IT хизмати | C15: 29.7 | D15: 72.9 | E15: =D15/$D$10 -> 0.10175879 | F15: =IFERROR(D15/C15, "-") -> 2.4545455
A16: 1.5 | B16: GameDev / Mobile / AI / FinTech | C16: 58.4 | D16: 98.4 | E16: =D16/$D$10 -> 0.13735343 | F16: =IFERROR(D16/C16, "-") -> 1.6849315
A17: 2 | B17: Экспорт географияси
A18: 2.1 | B18: Осийо-Тинч океани минтақаси | C18: 56.064 | D18: 77.9 | E18: =D18/$D$10 -> 0.10873814 | F18: =IFERROR(D18/C18, "-") -> 1.3894834
A19: 2.2 | B19: Шимолий Америка | C19: 210.24 | D19: 324.5 | E19: =D19/$D$10 -> 0.45295924 | F19: =IFERROR(D19/C19, "-") -> 1.5434741
A20: 2.3 | B20: Европа (+Буюк Британия) | C20: 97.312 | D20: 168.5 | E20: =D20/$D$10 -> 0.2352038 | F20: =IFERROR(D20/C20, "-") -> 1.7315439
A21: 2.4 | B21: Яқин Шарқ | C21: 28.032 | D21: 35.33 | E21: =D21/$D$10 -> 0.049316025 | F21: =IFERROR(D21/C21, "-") -> 1.2603453
A22: 2.5 | B22: МДХ | C22: 74.752 | D22: 110.12 | E22: =D22/$D$10 -> 0.15371301 | F22: =IFERROR(D22/C22, "-") -> 1.4731378
A23: 3 | B23: Хамкор мамлакатлар сони | C23: 86 | D23: 94 | E23: х | F23: =IFERROR(D23/C23, "-") -> 1.0930233
A24: 4 | B24: Экспортчилар сони | C24: 650 | D24: 900 | E24: 1 | F24: =IFERROR(D24/C24, "-") -> 1.3846154
B25: шу жумладан, хорижий резидентлар | C25: 284 | D25: 382 | E25: =D25/D24 -> 0.42444444 | F25: =IFERROR(D25/C25, "-") -> 1.3450704

Sheet 3.1-жадвал
F1: 3.1-жадвал
A2: Мамлакатлар бўйича IT хизматлари экспорти
F3: млн. АҚШ долл.
A4: № | B4: Мамлакат | C4: ='2-жадвал'!C5 -> 2024-йил | D4: ='2-жадвал'!D5 -> 2025-йил | E4: Улуши | F4: Ўсиш суръати
B6: Жами | C6: ='2-жадвал'!C11 -> 466.4 | D6: ='2-жадвал'!D11 -> 716.4 | E6: =SUM(E7:E474) -> 0.99995651 | F6: =D6/C6 -> 1.5360206 | H6: =SUM(C7:C518)-C6 -> 0.049025388 | I6: =SUM(D7:D518)-D6 -> -0.031153538
A7: 1 | B7: АҚШ | C7: 211.53581 | D7: 320.30288 | E7: =D7/$D$6 -> 0.44710061 | F7: =IFERROR(D7/C7, "-") -> 1.514178
A8: 2 | B8: Россия | C8: 62.846856 | D8: 81.571247 | E8: =D8/$D$6 -> 0.11386271 | F8: =IFERROR(D8/C8, "-") -> 1.2979368
A9: 3 | B9: Бирлашган Қироллик | C9: 33.212988 | D9: 49.169852 | E9: =D9/$D$6 -> 0.068634634 | F9: =IFERROR(D9/C9, "-") -> 1.4804405
A10: 4 | B10: Кипр | C10: 15.118613 | D10: 48.753743 | E10: =D10/$D$6 -> 0.068053801 | F10: =IFERROR(D10/C10, "-") -> 3.2247496
A11: 5 | B11: БАА | C11: 25.577126 | D11: 31.714376 | E11: =D11/$D$6 -> 0.04426909 | F11: =IFERROR(D11/C11, "-") -> 1.2399507
A12: 6 | B12: Сингапур | C12: 28.4 | D12: 30.293815 | E12: =D12/$D$6 -> 0.042286174 | F12: =IFERROR(D12/C12, "-") -> 1.0666836
A13: 7 | B13: Хитой | C13: 2.7503113 | D13: 22.198084 | E13: =D13/$D$6 -> 0.0309856 | F13: =IFERROR(D13/C13, "-") -> 8.0711168
A14: 8 | B14: Қозоғистон | C14: 12.070991 | D14: 17.615123 | E14: =D14/$D$6 -> 0.024588391 | F14: =IFERROR(D14/C14, "-") -> 1.4592939
A15: 9 | B15: Гонконг | C15: 6.6099415 | D15: 16.033714 | E15: =D15/$D$6 -> 0.022380952 | F15: =IFERROR(D15/C15, "-") -> 2.4256968
A16: 10 | B16: Ирландия | C16: 4.5725358 | D16: 11.53411 | E16: =D16/$D$6 -> 0.016100098 | F16: =IFERROR(D16/C16, "-") -> 2.5224757
A17: 11 | B17: Норвегия | C17: 10.456699 | D17: 8.8492379 | E17: =D17/$D$6 -> 0.01235237 | F17: =IFERROR(D17/C17, "-") -> 0.84627449
A18: 12 | B18: Туркия | C18: 5.311399 | D18: 8.4641776 | E18: =D18/$D$6 -> 0.011814877 | F18: =IFERROR(D18/C18, "-") -> 1.5935872
... A110: 104 | B110: Уганда | C110: 0.0068 | D110: 0 | E110: =D110/$D$6 -> 0 | F110: =IFERROR(D110/C110, "-") -> 0

Sheet 3.2-жадвал
F1: 3.2-жадвал
A3: ТОП-10 экспортчилар (IT-Park резидентлари)
F4: млн. АҚШ долл.
A5: № | B5: Кўрсаткич номи | C5: ='2-жадвал'!C5 -> 2024-йил | D5: ='2-жадвал'!D5 -> 2025-йил | E5: Улуши | F5: Ўсиш суръати
B7: Жами | C7: ='2-жадвал'!C11 -> 466.4 | D7: ='2-жадвал'!D11 -> 716.4 | E7: =E8+E10+E12+E14+E16+E18+E20+E22+E24+E27 -> 0.24995594 | F7: =D7/C7 -> 1.5360206
A8: 1 | B8: "EAST-GAMES" МЧЖ | C8: 40.331401 | D8: 50.604421 | E8: =D8/$D$7 -> 0.070637103 | F8: =IFERROR(D8/C8, "-") -> 1.2547152
B9: Дастур ишлаб чиқиш
A10: 2 | B10: "VENTION" МЧЖ ХК | C10: 7.2029651 | D10: 27.970007 | E10: =D10/$D$7 -> 0.039042445 | F10: =IFERROR(D10/C10, "-") -> 3.8831241
B11: Дастур ишлаб чиқиш
A12: 3 | B12: "EPAM SYSTEMS" МЧЖ | C12: 20.977129 | D12: 22.22774 | E12: =D12/$D$7 -> 0.031026996 | F12: =IFERROR(D12/C12, "-") -> 1.0596178
B13: Дастур ишлаб чиқиш
A14: 4 | B14: "ITRANSITION" МЧЖ | C14: 23.248762 | D14: 20.355433 | E14: =D14/$D$7 -> 0.028413503 | F14: =IFERROR(D14/C14, "-") -> 0.87554914
B15: Дастур ишлаб чиқиш
A16: 5 | B16: "INNOTECH SOLUTIONS" МЧЖ | C16: 0 | D16: 13 | E16: =D16/$D$7 -> 0.018146287 | F16: =IFERROR(D16/C16, "-") -> -
B17: Дастур ишлаб чиқиш
A18: 6 | B18: "TEZ IT SOLUTIONS" МЧЖ | C18: 2.27 | D18: 12.3935 | E18: =D18/$D$7 -> 0.017299693 | F18: =IFERROR(D18/C18, "-") -> 5.4596916
B19: Геймдев
A20: 7 | B20: "HITECH SOFTWARE" МЧЖ | C20: 0 | D20: 11.562982 | E20: =D20/$D$7 -> 0.016140399 | F20: =IFERROR(D20/C20, "-") -> -
B21: Лицензияни жорий этиш
A22: 8 | B22: "IBD-SOFT" МЧЖ | C22: 0 | D22: 10.547751 | E22: =D22/$D$7 -> 0.01472327 | F22: =IFERROR(D22/C22, "-") -> -
B23: Дастур ишлаб чиқиш
A24: 9 | B24: "SOFTWARE WIZARDS" МЧЖ | C24: 9.7543 | D24: 10.4066 | E24: =D24/$D$7 -> 0.014526242 | F24: =IFERROR(D24/C24, "-") -> 1.0668731
B25: Дастур ишлаб чиқиш
A26: 10 | B26: "ART-KAR" МЧЖ | C26: 0 | D26: 10.098332 | E26: =D26/$D$7 -> 0.014095941 | F26: =IFERROR(D26/C26, "-") -> -
B27: Дастур ишлаб чиқиш

Sheet 3.3-жадвал
G1: 3.3-жадвал
A3: Экспорт хажмини оширган IT-Park резидентлари
G4: млн. АҚШ долл.
A5: № | B5: Кўрсаткич номи | C5: ='2-жадвал'!C5 -> 2024-йил | D5: ='2-жадвал'!D5 -> 2025-йил | E5: Улуши | F5: Сони | G5: Ўсиш суръати
B7: Жами | C7: 250.19344 | D7: 595.71848 | E7: 1 | F7: 435 | G7: =IFERROR(D7/C7, "-") -> 2.3810316
B8: шу жумладан:
B9: BPO / autsorsing | C9: 72.704876 | D9: 175.49232 | E9: =+D9/$D$7 -> 0.29458935 | F9: 170 | G9: =IFERROR(D9/C9, "-") -> 2.4137628
B10: HQ | C10: 5.0815051 | D10: 20.821685 | E10: =+D10/$D$7 -> 0.034952223 | F10: 22 | G10: =IFERROR(D10/C10, "-") -> 4.0975429
B11: IT бўйича тренинг | C11: 0.54841211 | D11: 3.8870165 | E11: =+D11/$D$7 -> 0.0065249217 | F11: 5 | G11: =IFERROR(D11/C11, "-") -> 7.0877656
B12: IT хизмати | C12: 126.7045 | D12: 311.07195 | E12: =+D12/$D$7 -> 0.52217945 | F12: 222 | G12: =IFERROR(D12/C12, "-") -> 2.4550979
B13: GameDev / Mobil / AI / FinTech | C13: 45.154145 | D13: 84.445507 | E13: =+D13/$D$7 -> 0.14175405 | F13: 16 | G13: =IFERROR(D13/C13, "-") -> 1.8701607
B14: ТОП-10
A15: 1 | B15: "EAST-GAMES" МЧЖ | C15: 40.331401 | D15: 50.604421 | E15: =D15/$D$7 -> 0.084946871 | F15: х | G15: =IFERROR(D15/C15, "-") -> 1.2547152
A16: 2 | B16: "VENTION" МЧЖ ХК | C16: 7.2029651 | D16: 27.970007 | E16: =D16/$D$7 -> 0.04695172 | F16: х | G16: =IFERROR(D16/C16, "-") -> 3.8831241
A17: 3 | B17: "TEZ IT SOLUTIONS" МЧЖ | C17: 2.27 | D17: 12.3935 | E17: =D17/$D$7 -> 0.02080429 | F17: х | G17: =IFERROR(D17/C17, "-") -> 5.4596916
A18: 4 | B18: "ART-KAR" МЧЖ | C18: 0 | D18: 10.098332 | E18: =D18/$D$7 -> 0.016951517 | F18: х | G18: =IFERROR(D18/C18, "-") -> -
A19: 5 | B19: "SHARQ IT LAB" МЧЖ | C19: 1.2943482 | D19: 9.5935881 | E19: =D19/$D$7 -> 0.016104231 | F19: х | G19: =IFERROR(D19/C19, "-") -> 7.4119068
A20: 6 | B20: "DEVEXPERTS SOUTH" МЧЖ | C20: 0.904568 | D20: 8.167554 | E20: =D20/$D$7 -> 0.013710426 | F20: х | G20: =IFERROR(D20/C20, "-") -> 9.0292316
A21: 7 | B21: "CYBREX" МЧЖ ХК | C21: 0.31007522 | D21: 5.836978 | E21: =D21/$D$7 -> 0.0097982154 | F21: х | G21: =IFERROR(D21/C21, "-") -> 18.824394
A22: 8 | B22: "KEENEO" МЧЖ | C22: 1.1963548 | D22: 5.3249799 | E22: =D22/$D$7 -> 0.0089387522 | F22: х | G22: =IFERROR(D22/C22, "-") -> 4.4510039
A23: 9 | B23: "ON TIME-SOLUTIONS" МЧЖ | C23: 0.564271 | D23: 5.0586566 | E23: =D23/$D$7 -> 0.0084916899 | F23: х | G23: =IFERROR(D23/C23, "-") -> 8.9649417
A24: 10 | B24: "BOOSTANDSALES" МЧЖ | C24: 0 | D24: 4.9032379 | E24: =D24/$D$7 -> 0.0082307971 | F24: х | G24: =IFERROR(D24/C24, "-") -> -

Sheet 3.4-жадвал
G1: 3.4-жадвал
A3: Экспорт хажмини камайтирган IT-Park резидентлари
G4: млн. АҚШ долл.
A5: № | B5: Кўрсаткич номи | C5: ='2-жадвал'!C5 -> 2024-йил | D5: ='2-жадвал'!D5 -> 2025-йил | E5: Улуши | F5: Сони | G5: Ўсиш суръати
B7: Жами | C7: 216.17197 | D7: 120.63316 | E7: 1 | F7: 344 | G7: =IFERROR(D7/C7, "-") -> 0.55804256
B8: шу жумладан:
B9: BPO / autsorsing | C9: 47.06821 | D9: 27.496483 | E9: 0.22793469 | F9: 89 | G9: =IFERROR(D9/C9, "-") -> 0.58418373
B10: HQ | C10: 1.169707 | D10: 0.9525356 | E10: 0.0078961339 | F10: 3 | G10: =IFERROR(D10/C10, "-") -> 0.81433692
B11: IT бўйича тренинг | C11: 0.999183 | D11: 0.563344 | E11: 0.0046698934 | F11: 10 | G11: =IFERROR(D11/C11, "-") -> 0.56380463
B12: IT хизмати | C12: 165.50558 | D12: 90.722469 | E12: 0.75205249 | F12: 231 | G12: =IFERROR(D12/C12, "-") -> 0.54815353
B13: GameDev / Mobil / AI / FinTech | C13: 1.4292891 | D13: 0.89833054 | E13: 0.0074467959 | F13: 11 | G13: =IFERROR(D13/C13, "-") -> 0.62851562
B14: ТОП-10
A15: 1 | B15: "UNIPAYMENT" МЧЖ ХК | C15: 6.003 | D15: 0 | E15: =D15/$D$7 -> 0 | F15: х | G15: =IFERROR(D15/C15, "-") -> 0
A16: 2 | B16: "OPEN TRAVEL MARKET" МЧЖ | C16: 6 | D16: 0 | E16: =D16/$D$7 -> 0 | F16: х | G16: =IFERROR(D16/C16, "-") -> 0
A17: 3 | B17: "GENWARE IT COMPANY" МЧЖ | C17: 5.5 | D17: 0 | E17: =D17/$D$7 -> 0 | F17: х | G17: =IFERROR(D17/C17, "-") -> 0
A18: 4 | B18: "KOMPRA" МЧЖ | C18: 4.88 | D18: 0 | E18: =D18/$D$7 -> 0 | F18: х | G18: =IFERROR(D18/C18, "-") -> 0
A19: 5 | B19: "DEEPINSIGHT" МЧЖ | C19: 3.8 | D19: 0 | E19: =D19/$D$7 -> 0 | F19: х | G19: =IFERROR(D19/C19, "-") -> 0
A20: 6 | B20: "IT LOGISTIC-GLOBAL" МЧЖ | C20: 2.966 | D20: 0.0736 | E20: =D20/$D$7 -> 0.00061011416 | F20: х | G20: =IFERROR(D20/C20, "-") -> 0.024814565
A21: 7 | B21: "TERRALINK" МЧЖ | C21: 3.250563 | D21: 0.23312814 | E21: =D21/$D$7 -> 0.0019325378 | F21: х | G21: =IFERROR(D21/C21, "-") -> 0.071719311
A22: 8 | B22: "HUMANS LAB" МЧЖ | C22: 7.1522246 | D22: 2.149 | E22: =D22/$D$7 -> 0.017814339 | F22: х | G22: =IFERROR(D22/C22, "-") -> 0.30046595
A23: 9 | B23: "AR-GLOBAL-LOGISTIC" МЧЖ | C23: 4.6781 | D23: 2.3736 | E23: =D23/$D$7 -> 0.019676182 | F23: х | G23: =IFERROR(D23/C23, "-") -> 0.50738548
A24: 10 | B24: "ITRANSITION" МЧЖ | C24: 23.248762 | D24: 20.355433 | E24: =D24/$D$7 -> 0.16873829 | F24: х | G24: =IFERROR(D24/C24, "-") -> 0.87554914

Sheet 4-жадвал
F1: 4-жадвал
A3: IT-Park резидентлари томонидан кўрсатилган хизматлар ҳажми
F4: млрд. сўм
A5: № | B5: Кўрсаткич номи | C5: ='2-жадвал'!C5 -> 2024-йил | D5: ='2-жадвал'!D5 -> 2025-йил | E5: Улуши | F5: Ўсиш суръати
A7: 1 | B7: Жами хизматлар | C7: ='2-жадвал'!C7 -> 20423 | D7: ='2-жадвал'!D7 -> 33405 | E7: =SUM(E9:E13) -> 1.000018 | F7: =IFERROR(D7/C7, "-") -> 1.6356559
B8: шу жумладан хизмат турлари бўйича:
A9: 1.1 | B9: BPO / autsorsing | C9: 1585.6 | D9: 2725.7 | E9: =D9/$D$7 -> 0.08159557 | F9: =IFERROR(D9/C9, "-") -> 1.7190338
A10: 1.2 | B10: HQ | C10: 86.056 | D10: 376.1 | E10: =D10/$D$7 -> 0.011258794 | F10: =IFERROR(D10/C10, "-") -> 4.37041
A11: 1.3 | B11: IT trening | C11: 213.9 | D11: 338.9 | E11: =D11/$D$7 -> 0.010145188 | F11: =IFERROR(D11/C11, "-") -> 1.5843852
A12: 1.4 | B12: IT хизмати | C12: 12353.7 | D12: 18889.6 | E12: =D12/$D$7 -> 0.56547223 | F12: =IFERROR(D12/C12, "-") -> 1.5290642
A13: 1.5 | B13: GameDev / Mobil / Sun'iy intellekt / FinTech | C13: 6184.3 | D13: 11075.3 | E13: =D13/$D$7 -> 0.33154618 | F13: =IFERROR(D13/C13, "-") -> 1.7908737
A14: 2 | B14: Жами хизматлар хажмида улуши юқори IT-Parkнинг ТОП-10 резиденти | C14: =SUM(C15:C24) -> 7507.0851 | D14: =SUM(D15:D24) -> 11833.301 | E14: =SUM(E15:E24) -> 35.423742 | F14: =IFERROR(D14/C14, "-") -> 1.5762844
A15: 2.1 | B15: "SOLUTIONS LAB" АЖ | C15: 1831.4888 | D15: 3444.608 | E15: =D15/$D$7*100 -> 10.311654 | F15: =IFERROR(D15/C15, "-") -> 1.8807694
A16: 2.2 | B16: "YAGONA UMUMRESPUBLIKA PROTSESSING MARKAZI" АЖ | C16: 1315.1402 | D16: 2215.0523 | E16: =D16/$D$7*100 -> 6.6309003 | F16: =IFERROR(D16/C16, "-") -> 1.6842708
A17: 2.3 | B17: GID SYSTEMS TASHKENT MCHJ XK | C17: 1228.3497 | D17: 1418.0437 | E17: =D17/$D$7*100 -> 4.2450043 | F17: =IFERROR(D17/C17, "-") -> 1.15443
A18: 2.4 | B18: "PAYME" АЖ | C18: 510.02832 | D18: 817.08181 | E18: =D18/$D$7*100 -> 2.4459866 | F18: =IFERROR(D18/C18, "-") -> 1.6020322
A19: 2.5 | B19: "CLICK" АЖ | C19: 612.57391 | D19: 789.41276 | E19: =D19/$D$7*100 -> 2.3631575 | F19: =IFERROR(D19/C19, "-") -> 1.2886817
A20: 2.6 | B20: "UZUM TECHNOLOGIES" МЧЖ ХК | C20: 517.32698 | D20: 732.81146 | E20: =D20/$D$7*100 -> 2.1937179 | F20: =IFERROR(D20/C20, "-") -> 1.4165344
A21: 2.7 | B21: "UZINFOCOM" МЧЖ | C21: 451.42206 | D21: 714.44927 | E21: =D21/$D$7*100 -> 2.1387495 | F21: =IFERROR(D21/C21, "-") -> 1.5826636
A22: 2.8 | B22: "EAST-GAMES" МЧЖ | C22: 541.47086 | D22: 673.61573 | E22: =D22/$D$7*100 -> 2.0165117 | F22: =IFERROR(D22/C22, "-") -> 1.244048
A23: 2.9 | B23: "UZUM AUTO" МЧЖ | C23: 499.28432 | D23: 519.18489 | E23: =D23/$D$7*100 -> 1.5542131 | F23: =IFERROR(D23/C23, "-") -> 1.0398582
A24: 2.10 | B24: "MILLIY BANKLARARO PROTSESSING MARKAZI" АЖ | C24: 0 | D24: 509.04132 | E24: =D24/$D$7*100 -> 1.5238477 | F24: =IFERROR(D24/C24, "-") -> -

Sheet 5-жадвал
I1: 5-жадвал
A2: 2025 йилларга мўлжалланган инвестицияларни ўзлаштириш кўрсаткичлари
I3: млн. АҚШ долл.
A4: Т/р | B4: Лойиҳа ташаббускорлари ва лойиҳа номи | C4: Лойиҳа умумий қиймати | D4: режа | E4: амалда | F4: бажари-лиши | G4: Расмий статистика | I4: 2026 йилга таклиф
G5: амалда | H5: бажарилиши
A7: 1 | B7: Жами ўзлаштирилган инвестициялар | C7: 150 | D7: 53 | E7: 164.6 | F7: =IFERROR(E7/D7, "-") -> 3.1056604 | G7: 35 | H7: =+G7/D7 -> 0.66037736 | I7: =+I8+I9 -> 238
A8: 1.1. | B8: ўз маблағлари | C8: 15 | E8: 77.9 | F8: =IFERROR(E8/D8, "-") -> - | I8: =+I12+I14+I19 -> 105
A9: 1.2. | B9: тўғридан-тўғри хорижий инвестиция ва кредит | C9: 135 | D9: 53 | E9: 86.7 | F9: =IFERROR(E9/D9, "-") -> 1.6358491 | G9: 35 | H9: =+G9/D9 -> 0.66037736 | I9: =+I15+I17+I20 -> 133
B10: шу жумладан:
A11: 2 | B11: IT Park мажмуасининг 2-босқичини қуриш | E11: 7.2 | F11: =IFERROR(E11/D11, "-") -> - | I11: 70
B12: ўз маблағлари | E12: 7.2 | F12: =IFERROR(E12/D12, "-") -> - | I12: 70
A13: 3 | B13: IT Park резидентлари томонидан | D13: 50 | E13: 154.4 | F13: =IFERROR(E13/D13, "-") -> 3.088 | G13: 32 | H13: =+G13/D13 -> 0.64 | I13: 100
B14: ўз маблағлари | E14: 70.7 | F14: =IFERROR(E14/D14, "-") -> - | I14: 20
B15: тўғридан-тўғри хорижий инвестисия ва кредит | D15: 50 | E15: 83.7 | F15: =IFERROR(E15/D15, "-") -> 1.674 | G15: 32 | H15: =+G15/D15 -> 0.64 | I15: 80
A16: 4 | B16: Ўзбекистонда рақамли инклюзивлик | C16: 50 | D16: 3 | E16: 3 | F16: =IFERROR(E16/D16, "-") -> 1 | G16: 3 | H16: =+G16/D16 -> 1 | I16: 10
B17: Давлат кафолати остидаги хорижий кредит | C17: 50 | D17: 3 | E17: 3 | F17: =IFERROR(E17/D17, "-") -> 1 | I17: 10
A18: 5 | B18: “Shanghai Construction Group” (Хитой) компанияси “fast track” услубида IT Park биноларини қуриш | C18: 100 | F18: =IFERROR(E18/D18, "-") -> - | I18: 58
B19: ўз маблағлари | C19: 15 | F19: =IFERROR(E19/D19, "-") -> - | I19: 15
B20: тўғридан-тўғри хорижий инвестиция ва кредит | C20: 85 | F20: =IFERROR(E20/D20, "-") -> - | I20: 43
A21: 6 | B21: Стартап лойиҳаларга венчур инвестициялар | F21: =IFERROR(E21/D21, "-") -> -

Sheet 6-жадвал
L1: 6-жадвал
A2: 2025-йил учун вилоятлар кесимида маълумот
A4: Кўрсаткич номи | B4: Резидент-лар сони | C4: Улуши | D4: Ўсиш суръати | E4: Ходимлар сони | G4: Хизматлар (млрд. сўм) | J4: Экспорт (млн. АҚШ долл.)
E5: Жами | F5: Ўсиш суръати | G5: Жами | H5: Улуши | I5: Ўсиш суръати | J5: Жами | K5: Улуши | L5: Ўсиш суръати
A6: Жами | B6: =B7+B8 -> 3435 | C6: =C7+C8 -> 1 | D6: =IFERROR(B6/B29, "-") -> 1.3211538 | E6: =E7+E8 -> 53026 | F6: =IFERROR(E6/E29, "-") -> 1.3719179 | G6: =G7+G8 -> 33405.282 | H6: =H7+H8 -> 1 | I6: =IFERROR(G6/G29, "-") -> 1.6356456 | J6: =J7+J8 -> 716.42957 | K6: =K7+K8 -> 1 | L6: =IFERROR(J6/J29, "-") -> 1.5359411
A7: IT Park | B7: 2057 | C7: =B7/$B$6 -> 0.59883552 | D7: =IFERROR(B7/B30, "-") -> 1.4069767 | E7: 38684 | F7: =IFERROR(E7/E30, "-") -> 1.333885 | G7: 30040.584 | H7: =G7/$G$6 -> 0.89927648 | I7: =IFERROR(G7/G30, "-") -> 1.6062079 | J7: 558.90653 | K7: =J7/$J$6 -> 0.78012767 | L7: =IFERROR(J7/J30, "-") -> 1.4399393
A8: Худудлар | B8: 1378 | C8: =B8/$B$6 -> 0.40116448 | D8: =IFERROR(B8/B31, "-") -> 1.2108963 | E8: 14342 | F8: =IFERROR(E8/E31, "-") -> 1.4862176 | G8: 3364.6976 | H8: =G8/$G$6 -> 0.10072352 | I8: =IFERROR(G8/G31, "-") -> 1.955651 | J8: 157.52304 | K8: =J8/$J$6 -> 0.21987233 | L8: =IFERROR(J8/J31, "-") -> 2.0118527
A9: шу жумладан:
A10: Қорақалпоғистон Республикаси | B10: 105 | C10: =B10/$B$6 -> 0.030567686 | D10: =IFERROR(B10/B33, "-") -> 0.88235294 | E10: 1574 | F10: =IFERROR(E10/E33, "-") -> 3.5936073 | G10: 174.82593 | H10: =G10/$G$6 -> 0.0052334816 | I10: =IFERROR(G10/G33, "-") -> 3.6728136 | J10: 7.0670407 | K10: =J10/$J$6 -> 0.0098642505 | L10: =IFERROR(J10/J33, "-") -> 2.8232026
A11: Андижон | B11: 96 | C11: =B11/$B$6 -> 0.027947598 | D11: =IFERROR(B11/B34, "-") -> 1.4328358 | E11: 1415 | F11: =IFERROR(E11/E34, "-") -> 1.6006787 | G11: 445.88911 | H11: =G11/$G$6 -> 0.013347862 | I11: =IFERROR(G11/G34, "-") -> 2.4037149 | J11: 25.960454 | K11: =J11/$J$6 -> 0.036235877 | L11: =IFERROR(J11/J34, "-") -> 2.0221572
A12: Бухоро | B12: 67 | C12: =B12/$B$6 -> 0.019505095 | D12: =IFERROR(B12/B35, "-") -> 1.1551724 | E12: 636 | F12: =IFERROR(E12/E35, "-") -> 1.3978022 | G12: 134.0374 | H12: =G12/$G$6 -> 0.0040124612 | I12: =IFERROR(G12/G35, "-") -> 2.2414281 | J12: 7.6985636 | K12: =J12/$J$6 -> 0.010745737 | L12: =IFERROR(J12/J35, "-") -> 2.101079
A13: Жиззах | B13: 65 | C13: =B13/$B$6 -> 0.018922853 | D13: =IFERROR(B13/B36, "-") -> 1.0483871 | E13: 382 | F13: =IFERROR(E13/E36, "-") -> 1.2993197 | G13: 148.94693 | H13: =G13/$G$6 -> 0.0044587839 | I13: =IFERROR(G13/G36, "-") -> 2.3200457 | J13: 9.5503912 | K13: =J13/$J$6 -> 0.013330538 | L13: =IFERROR(J13/J36, "-") -> 2.3024087
A14: Қашқадарйо | B14: 67 | C14: =B14/$B$6 -> 0.019505095 | D14: =IFERROR(B14/B37, "-") -> 1.0307692 | E14: 666 | F14: =IFERROR(E14/E37, "-") -> 1.3033268 | G14: 78.671512 | H14: =G14/$G$6 -> 0.0023550621 | I14: =IFERROR(G14/G37, "-") -> 1.1992609 | J14: 2.4738602 | K14: =J14/$J$6 -> 0.0034530403 | L14: =IFERROR(J14/J37, "-") -> 1.003961
A15: Навоий | B15: 53 | C15: =B15/$B$6 -> 0.015429403 | D15: =IFERROR(B15/B38, "-") -> 0.98148148 | E15: 423 | F15: =IFERROR(E15/E38, "-") -> 1.5962264 | G15: 88.269268 | H15: =G15/$G$6 -> 0.0026423746 | I15: =IFERROR(G15/G38, "-") -> 1.0738354 | J15: 3.8240542 | K15: =J15/$J$6 -> 0.0053376555 | L15: =IFERROR(J15/J38, "-") -> 1.0780183
A16: Наманган | B16: 77 | C16: =B16/$B$6 -> 0.022416303 | D16: =IFERROR(B16/B39, "-") -> 1.1492537 | E16: 481 | F16: =IFERROR(E16/E39, "-") -> 1.1082949 | G16: 63.815586 | H16: =G16/$G$6 -> 0.0019103442 | I16: =IFERROR(G16/G39, "-") -> 1.1436485 | J16: 2.1908043 | K16: =J16/$J$6 -> 0.003057948 | L16: =IFERROR(J16/J39, "-") -> 0.94480091
A17: Самарқанд | B17: 192 | C17: =B17/$B$6 -> 0.055895197 | D17: =IFERROR(B17/B40, "-") -> 1.3617021 | E17: 2170 | F17: =IFERROR(E17/E40, "-") -> 1.3742875 | G17: 404.1566 | H17: =G17/$G$6 -> 0.012098584 | I17: =IFERROR(G17/G40, "-") -> 2.020783 | J17: 19.852511 | K17: =J17/$J$6 -> 0.027710345 | L17: =IFERROR(J17/J40, "-") -> 1.8869594
A18: Сурхондарйо | B18: 76 | C18: =B18/$B$6 -> 0.022125182 | D18: =IFERROR(B18/B41, "-") -> 1.2258065 | E18: 587 | F18: =IFERROR(E18/E41, "-") -> 2.2576923 | G18: 136.52575 | H18: =G18/$G$6 -> 0.0040869509 | I18: =IFERROR(G18/G41, "-") -> 1.7570881 | J18: 3.3341204 | K18: =J18/$J$6 -> 0.0046538007 | L18: =IFERROR(J18/J41, "-") -> 1.0602685
A19: Сирдарйо | B19: 66 | C19: =B19/$B$6 -> 0.019213974 | D19: =IFERROR(B19/B42, "-") -> 1.2 | E19: 480 | F19: =IFERROR(E19/E42, "-") -> 1.1428571 | G19: 52.543517 | H19: =G19/$G$6 -> 0.0015729105 | I19: =IFERROR(G19/G42, "-") -> 1.3335918 | J19: 2.2682576 | K19: =J19/$J$6 -> 0.0031660581 | L19: =IFERROR(J19/J42, "-") -> 1.2380643
A20: Тошкент | B20: 193 | C20: =B20/$B$6 -> 0.056186317 | D20: =IFERROR(B20/B43, "-") -> 1.4087591 | E20: 1722 | F20: =IFERROR(E20/E43, "-") -> 1.5065617 | G20: 796.63088 | H20: =G20/$G$6 -> 0.023847453 | I20: =IFERROR(G20/G43, "-") -> 2.5516684 | J20: 34.549201 | K20: =J20/$J$6 -> 0.048224142 | L20: =IFERROR(J20/J43, "-") -> 3.4239335
A21: Фарғона | B21: 139 | C21: =B21/$B$6 -> 0.040465793 | D21: =IFERROR(B21/B44, "-") -> 1.3495146 | E21: 1917 | F21: =IFERROR(E21/E44, "-") -> 1.4252788 | G21: 429.44487 | H21: =G21/$G$6 -> 0.012855598 | I21: =IFERROR(G21/G44, "-") -> 2.6640501 | J21: 22.76973 | K21: =J21/$J$6 -> 0.031782232 | L21: =IFERROR(J21/J44, "-") -> 3.767328
... A23: Тошкент ш. | B23: 70 | C23: =B23/$B$6 -> 0.020378457 | D23: =IFERROR(B23/B46, "-") -> 1.1111111 | E23: 850 | F23: =IFERROR(E23/E46, "-") -> 1.0340633 | G23: 171.271 | H23: =G23/$G$6 -> 0.0051270635 | I23: =IFERROR(G23/G46, "-") -> 1.0280372 | J23: 11.32396 | K23: =J23/$J$6 -> 0.015806104 | L23: =IFERROR(J23/J46, "-") -> 1.0849303
A28: O'tgan yili
A29: ЖАМИ | B29: =B30+B31 -> 2600 | E29: =E30+E31 -> 38651 | G29: =G30+G31 -> 20423.3 | J29: 466.4434
A30: ИТ Парк | B30: 1462 | E30: 29001 | G30: 18702.8 | J30: 388.1459
A31: Худудлар | B31: =SUM(B33:B46) -> 1138 | E31: =SUM(E33:E46) -> 9650 | G31: =SUM(G33:G46) -> 1720.5 | J31: 78.2975
A32: шу жумладан:
A33: Қорақалпогʻистон Республикаси | B33: 119 | E33: 438 | G33: 47.6 | J33: 2.5032
A34: Андижон | B34: 67 | E34: 884 | G34: 185.5 | J34: 12.838
A35: Бухоро | B35: 58 | E35: 455 | G35: 59.8 | J35: 3.6641
A36: Жиззах | B36: 62 | E36: 294 | G36: 64.2 | J36: 4.148
A37: Қашқадарйо | B37: 65 | E37: 511 | G37: 65.6 | J37: 2.4641
A38: Навоий | B38: 54 | E38: 265 | G38: 82.2 | J38: 3.5473
A39: Наманган | B39: 67 | E39: 434 | G39: 55.8 | J39: 2.3188
A40: Самарқанд | B40: 141 | E40: 1579 | G40: 200 | J40: 10.5209
A41: Сурхондарйо | B41: 62 | E41: 260 | G41: 77.7 | J41: 3.1446
A42: Сирдарйо | B42: 55 | E42: 420 | G42: 39.4 | J42: 1.8321
A43: Тошкент | B43: 137 | E43: 1143 | G43: 312.2 | J43: 10.0905
A44: Фарғона | B44: 103 | E44: 1345 | G44: 161.2 | J44: 6.044
... A46: Тошкент ш. | B46: 63 | E46: 822 | G46: 166.6 | J46: 10.4375

Sheet 6.1-жадвал
M1: 6.1-жадвал
A2: Расмий статистика - АКТ хизматлар ҳажм (Миллий статистика қўмитаси маълумотлари)
A4: Кўрсаткич номи | B4: Алоқа ва ахборотлаштириш (АКТ) хизматлари | H4: шу жумладан: компьютер дастурлаш хизматлари
B5: 2024 йил | E5: 2025 йил | H5: 2024 йил | K5: 2025 йил
B6: млрд. сўм | C6: Ўсиш суръати | D6: Улуши | E6: млрд. сўм | F6: Ўсиш суръати | G6: Улуши | H6: млрд. сўм | I6: Ўсиш суръати | J6: Улуши | K6: млрд. сўм | L6: Ўсиш суръати | M6: Улуши
A7: Ўзбекистон Республикаси | B7: =SUM(B8:B22) -> 56807.1 | C7: =IFERROR(B7/B28, "-") -> 1.4296777 | D7: =SUM(D8:D22) -> 1 | E7: =SUM(E8:E22) -> 79459.4 | F7: =IFERROR(E7/E28, "-") -> 1.3987583 | G7: =SUM(G8:G22) -> 1 | H7: =SUM(H8:H22) -> 22487.4 | I7: =IFERROR(H7/H28, "-") -> 1.55 | J7: =SUM(J8:J22) -> 1 | K7: =SUM(K8:K22) -> 34366.2 | L7: =IFERROR(K7/K28, "-") -> 1.5282425 | M7: =SUM(M8:M22) -> 1
A8: Қорақалпоғистон Республикаси | B8: 978.1 | C8: =IFERROR(B8/B29, "-") -> 1.2694354 | D8: =B8/$B$7 -> 0.017217918 | E8: 1403.2 | F8: =IFERROR(E8/E29, "-") -> 1.4346181 | G8: =E8/$E$7 -> 0.017659333 | H8: 91.7 | I8: =IFERROR(H8/H29, "-") -> 1.509 | J8: =H8/$H$7 -> 0.0040778391 | K8: 218.8 | L8: =IFERROR(K8/K29, "-") -> 2.3860414 | M8: =K8/$K$7 -> 0.0063667208
A9: шу жумладан:
A10: Андижон | B10: 1410.2 | C10: =IFERROR(B10/B31, "-") -> 1.2560791 | D10: =B10/$B$7 -> 0.024824362 | E10: 1797.7 | F10: =IFERROR(E10/E31, "-") -> 1.2747837 | G10: =E10/$E$7 -> 0.022624133 | H10: 129.6 | I10: =IFERROR(H10/H31, "-") -> 1.714 | J10: =H10/$H$7 -> 0.0057632274 | K10: 213.9 | L10: =IFERROR(K10/K31, "-") -> 1.650463 | M10: =K10/$K$7 -> 0.0062241388
A11: Бухоро | B11: 979.7 | C11: =IFERROR(B11/B32, "-") -> 1.2205058 | D11: =B11/$B$7 -> 0.017246084 | E11: 1299.2 | F11: =IFERROR(E11/E32, "-") -> 1.3261202 | G11: =E11/$E$7 -> 0.016350488 | H11: 85 | I11: =IFERROR(H11/H32, "-") -> 1.038 | J11: =H11/$H$7 -> 0.0037798945 | K11: 192.7 | L11: =IFERROR(K11/K32, "-") -> 2.2670588 | M11: =K11/$K$7 -> 0.0056072536
A12: Жиззах | B12: 696.3 | C12: =IFERROR(B12/B33, "-") -> 1.4503228 | D12: =B12/$B$7 -> 0.012257271 | E12: 1101.9 | F12: =IFERROR(E12/E33, "-") -> 1.5825075 | G12: =E12/$E$7 -> 0.013867459 | H12: 133.4 | I12: =IFERROR(H12/H33, "-") -> 3.105 | J12: =H12/$H$7 -> 0.0059322109 | K12: 369.1 | L12: =IFERROR(K12/K33, "-") -> 2.7668666 | M12: =K12/$K$7 -> 0.010740204
A13: Қашқадарйо | B13: 1364.9 | C13: =IFERROR(B13/B34, "-") -> 1.2597139 | D13: =B13/$B$7 -> 0.024026926 | E13: 1802.8 | F13: =IFERROR(E13/E34, "-") -> 1.3208294 | G13: =E13/$E$7 -> 0.022688316 | H13: 131.9 | I13: =IFERROR(H13/H34, "-") -> 1.151 | J13: =H13/$H$7 -> 0.0058655069 | K13: 262.7 | L13: =IFERROR(K13/K34, "-") -> 1.9916603 | M13: =K13/$K$7 -> 0.0076441387
A14: Навоий | B14: 674.5 | C14: =IFERROR(B14/B35, "-") -> 1.3280173 | D14: =B14/$B$7 -> 0.011873516 | E14: 963.2 | F14: =IFERROR(E14/E35, "-") -> 1.4280208 | G14: =E14/$E$7 -> 0.012121914 | H14: 134 | I14: =IFERROR(H14/H35, "-") -> 2.045 | J14: =H14/$H$7 -> 0.0059588925 | K14: 278.6 | L14: =IFERROR(K14/K35, "-") -> 2.0791045 | M14: =K14/$K$7 -> 0.0081068026
A15: Наманган | B15: 1181.8 | C15: =IFERROR(B15/B36, "-") -> 1.1731189 | D15: =B15/$B$7 -> 0.020803738 | E15: 1590.7 | F15: =IFERROR(E15/E36, "-") -> 1.3459976 | G15: =E15/$E$7 -> 0.020019029 | H15: 86 | I15: =IFERROR(H15/H36, "-") -> 0.752 | J15: =H15/$H$7 -> 0.0038243639 | K15: 183.7 | L15: =IFERROR(K15/K36, "-") -> 2.1360465 | M15: =K15/$K$7 -> 0.0053453684
A16: Самарқанд | B16: 2002.3 | C16: =IFERROR(B16/B37, "-") -> 1.3340662 | D16: =B16/$B$7 -> 0.035247355 | E16: 2764.3 | F16: =IFERROR(E16/E37, "-") -> 1.3805624 | G16: =E16/$E$7 -> 0.034788836 | H16: 340.2 | I16: =IFERROR(H16/H37, "-") -> 1.85 | J16: =H16/$H$7 -> 0.015128472 | K16: 568.3 | L16: =IFERROR(K16/K37, "-") -> 1.6704879 | M16: =K16/$K$7 -> 0.016536597
A17: Сурхондарйо | B17: 1078.8 | C17: =IFERROR(B17/B38, "-") -> 1.2347488 | D17: =B17/$B$7 -> 0.018990584 | E17: 1428.3 | F17: =IFERROR(E17/E38, "-") -> 1.3239711 | G17: =E17/$E$7 -> 0.017975218 | H17: 162.2 | I17: =IFERROR(H17/H38, "-") -> 1.334 | J17: =H17/$H$7 -> 0.0072129281 | K17: 299.7 | L17: =IFERROR(K17/K38, "-") -> 1.8477189 | M17: =K17/$K$7 -> 0.008720778
A18: Сирдарйо | B18: 476.5 | C18: =IFERROR(B18/B39, "-") -> 1.2347758 | D18: =B18/$B$7 -> 0.008388036 | E18: 631.1 | F18: =IFERROR(E18/E39, "-") -> 1.3244491 | G18: =E18/$E$7 -> 0.0079424209 | H18: 45 | I18: =IFERROR(H18/H39, "-") -> 1.448 | J18: =H18/$H$7 -> 0.0020011206 | K18: 88.1 | L18: =IFERROR(K18/K39, "-") -> 1.9577778 | M18: =K18/$K$7 -> 0.0025635654
A19: Тошкент | B19: 1816.4 | C19: =IFERROR(B19/B40, "-") -> 1.3484781 | D19: =B19/$B$7 -> 0.031974876 | E19: 2566.7 | F19: =IFERROR(E19/E40, "-") -> 1.4130698 | G19: =E19/$E$7 -> 0.032302031 | H19: 228.4 | I19: =IFERROR(H19/H40, "-") -> 1.547 | J19: =H19/$H$7 -> 0.010156799 | K19: 467.3 | L19: =IFERROR(K19/K40, "-") -> 2.045972 | M19: =K19/$K$7 -> 0.013597663
A20: Фарғона | B20: 2081.9 | C20: =IFERROR(B20/B41, "-") -> 1.2387838 | D20: =B20/$B$7 -> 0.036648588 | E20: 2806.8 | F20: =IFERROR(E20/E41, "-") -> 1.3481916 | G20: =E20/$E$7 -> 0.0353237 | H20: 357.7 | I20: =IFERROR(H20/H41, "-") -> 1.222 | J20: =H20/$H$7 -> 0.015906686 | K20: 641.8 | L20: =IFERROR(K20/K41, "-") -> 1.794241 | M20: =K20/$K$7 -> 0.018675326
A21: Хоразм | B21: 1102.2 | C21: =IFERROR(B21/B42, "-") -> 1.5293465 | D21: =B21/$B$7 -> 0.019402504 | E21: 1534.4 | F21: =IFERROR(E21/E42, "-") -> 1.3921248 | G21: =E21/$E$7 -> 0.019310491 | H21: 163.5 | I21: =IFERROR(H21/H42, "-") -> 4.767 | J21: =H21/$H$7 -> 0.0072707383 | K21: 323.2 | L21: =IFERROR(K21/K42, "-") -> 1.9767584 | M21: =K21/$K$7 -> 0.0094045894
A22: Тошкент ш. | B22: 40963.5 | C22: =IFERROR(B22/B43, "-") -> 1.4935737 | D22: =B22/$B$7 -> 0.72109824 | E22: 57769.1 | F22: =IFERROR(E22/E43, "-") -> 1.4102579 | G22: =E22/$E$7 -> 0.72702663 | H22: 20398.8 | I22: =IFERROR(H22/H43, "-") -> 1.552 | J22: =H22/$H$7 -> 0.90712132 | K22: 30258.3 | L22: =IFERROR(K22/K43, "-") -> 1.4833373 | M22: =K22/$K$7 -> 0.88046685
A27: O'tgan yili
A28: Ўзбекистон Республикаси | B28: 39734.2 | E28: =B7 -> 56807.1 | H28: 14508 | K28: =H7 -> 22487.4
A29: Қорақалпоғистон Республикаси | B29: 770.5 | E29: =B8 -> 978.1 | H29: 60.768721 | K29: =H8 -> 91.7
A30: шу жумладан:
A31: Андижон | B31: 1122.7 | E31: =B10 -> 1410.2 | H31: 75.612602 | K31: =H10 -> 129.6
A32: Бухоро | B32: 802.7 | E32: =B11 -> 979.7 | H32: 81.888247 | K32: =H11 -> 85
A33: Жиззах | B33: 480.1 | E33: =B12 -> 696.3 | H33: 42.962963 | K33: =H12 -> 133.4
A34: Қашқадарйо | B34: 1083.5 | E34: =B13 -> 1364.9 | H34: 114.596 | K34: =H13 -> 131.9
A35: Навоий | B35: 507.9 | E35: =B14 -> 674.5 | H35: 65.525672 | K35: =H14 -> 134
A36: Наманган | B36: 1007.4 | E36: =B15 -> 1181.8 | H36: 114.3617 | K36: =H15 -> 86
A37: Самарқанд | B37: 1500.9 | E37: =B16 -> 2002.3 | H37: 183.89189 | K37: =H16 -> 340.2
A38: Сурхондарйо | B38: 873.7 | E38: =B17 -> 1078.8 | H38: 121.58921 | K38: =H17 -> 162.2
A39: Сирдарйо | B39: 385.9 | E39: =B18 -> 476.5 | H39: 31.077348 | K39: =H18 -> 45
A40: Тошкент | B40: 1347 | E40: =B19 -> 1816.4 | H40: 147.64059 | K40: =H19 -> 228.4
A41: Фарғона | B41: 1680.6 | E41: =B20 -> 2081.9 | H41: 292.71686 | K41: =H20 -> 357.7
A42: Хоразм | B42: 720.7 | E42: =B21 -> 1102.2 | H42: 34.298301 | K42: =H21 -> 163.5
A43: Тошкент ш. | B43: 27426.5 | E43: =B22 -> 40963.5 | H43: 13143.557 | K43: =H22 -> 20398.8

Sheet 7-жадвал
H1: 7-жадвал
A2: IT Park резидентлар сони тўғрисида маълумот (01.01.2026 йил холатига)
H3: бирлик
A4: № | B4: Кўрсаткич номи | C4: ='2-жадвал'!C5 -> 2024-йил | D4: ='2-жадвал'!D5 -> 2025-йил | E4: Улуши | F4: Ўсиш суръати | G4: Экспорт
G5: млн. АҚШ долл. | H5: Улуши
A6: 1 | B6: Жами резидентлар | C6: 2600 | D6: 3435 | E6: х | F6: =IFERROR(D6/C6, "-") -> 1.3211538 | G6: 716.4 | H6: х
A7: 2 | B7: Янги резидентлар (хисобот даврида) | C7: 1049 | D7: 835 | E7: =D7/$D$6 -> 0.24308588 | F7: =IFERROR(D7/C7, "-") -> 0.79599619 | G7: 65.516598 | H7: =G7/$G$6 -> 0.091452538
A8: 3 | B8: Кетган резидентлар (хисобот даврида) | C8: 330 | D8: 689 | E8: =D8/$D$6 -> 0.20058224 | F8: =IFERROR(D8/C8, "-") -> 2.0878788 | G8: 2.181 | H8: =G8/$G$6 -> 0.0030443886
A9: 4 | B9: Соф ўсиш | C9: =+C7-C8 -> 719 | D9: =+D7-D8 -> 146 | E9: х | F9: =IFERROR(D9/C9, "-") -> 0.20305981 | G9: х | H9: х
A10: 5 | B10: Фаолият йўналиши | C10: х | D10: х | E10: х | F10: х | G10: х | H10: х
A11: 5.1 | B11: Дастурий таъминотни ишлаб чиқиш | C11: 944 | D11: 1584 | E11: =D11/$D$6 -> 0.46113537 | F11: =IFERROR(D11/C11, "-") -> 1.6779661 | G11: 302.93303 | H11: =G11/$G$6 -> 0.42285459
A12: 5.2 | B12: BPO | C12: 320 | D12: 503 | E12: =D12/$D$6 -> 0.14643377 | F12: =IFERROR(D12/C12, "-") -> 1.571875 | G12: 204.10064 | H12: =G12/$G$6 -> 0.2848976
A13: 5.3 | B13: IT таълими | C13: 361 | D13: 502 | E13: =D13/$D$6 -> 0.14614265 | F13: =IFERROR(D13/C13, "-") -> 1.3905817 | G13: 3.9633605 | H13: =G13/$G$6 -> 0.005532329
A14: 5.4 | B14: Техник ёрдам | C14: 262 | D14: 366 | E14: =D14/$D$6 -> 0.10655022 | F14: =IFERROR(D14/C14, "-") -> 1.3969466 | G14: 28.41267 | H14: =G14/$G$6 -> 0.039660343
A15: 5.5 | B15: Лицензияни амалга ошириш | C15: 194 | D15: 229 | E15: =D15/$D$6 -> 0.066666667 | F15: =IFERROR(D15/C15, "-") -> 1.1804124 | G15: 43.045758 | H15: =G15/$G$6 -> 0.060086206
A16: 5.6 | B16: Креатив иқтисодиёт | C16: 63 | D16: 117 | E16: =D16/$D$6 -> 0.034061135 | F16: =IFERROR(D16/C16, "-") -> 1.8571429 | G16: 6.2536137 | H16: =G16/$G$6 -> 0.0087292207
A17: 5.7 | B17: Маълумотларни қайта ишлаш | C17: 78 | D17: 112 | E17: =D17/$D$6 -> 0.032605531 | F17: =IFERROR(D17/C17, "-") -> 1.4358974 | G17: 2.908342 | H17: =G17/$G$6 -> 0.0040596621
A18: 5.8 | B18: HQ | C18: 28 | D18: 95 | E18: =D18/$D$6 -> 0.027656477 | F18: =IFERROR(D18/C18, "-") -> 3.3928571 | G18: 20.978917 | H18: =G18/$G$6 -> 0.029283804
A19: 5.9 | B19: IT консалтинг | C19: 40 | D19: 58 | E19: =D19/$D$6 -> 0.016885007 | F19: =IFERROR(D19/C19, "-") -> 1.45 | G19: 3.2932094 | H19: =G19/$G$6 -> 0.0045968864
A20: 5.10 | B20: Дастурий таъминотдаги реклама майдони | C20: 23 | D20: 36 | E20: =D20/$D$6 -> 0.010480349 | F20: =IFERROR(D20/C20, "-") -> 1.5652174 | G20: 1.9153285 | H20: =G20/$G$6 -> 0.0026735462
A21: 5.11 | B21: Хостинг | C21: 13 | D21: 34 | E21: =D21/$D$6 -> 0.0098981077 | F21: =IFERROR(D21/C21, "-") -> 2.6153846 | G21: 1.6846605 | H21: =G21/$G$6 -> 0.0023515641
A22: 5.12 | B22: Финтех | C22: 20 | D22: 20 | E22: =D22/$D$6 -> 0.0058224163 | F22: =IFERROR(D22/C22, "-") -> 1 | G22: 0.56092617 | H22: =G22/$G$6 -> 0.00078297902
... A27: 5.17 | B27: ПАКни амалга ошириш | C27: 0 | D27: 1 | E27: =D27/$D$6 -> 0.00029112082 | F27: =IFERROR(D27/C27, "-") -> - | G27: 0 | H27: =G27/$G$6 -> 0

Sheet 7.1-жадвал
F1: 7.1-жадвал
A3: IT-park резидентлари регистри, (01.01.2026 йил, мамлакатлар кесимида)
F4: бирлик
A5: № | B5: Мамлакат | C5: ='2-жадвал'!C5 -> 2024-йил | D5: ='2-жадвал'!D5 -> 2025-йил | E5: Улуши | F5: Ўсиш суръати
B7: Жами | C7: =SUM(C8:C324) -> 2375 | D7: =SUM(D8:D324) -> 3695 | E7: =SUM(E8:E324) -> 1 | F7: =IFERROR(D7/C7, "-") -> 1.5557895
A8: 1 | B8: Ўзбекистон | C8: 1760 | D8: 2688 | E8: =D8/$D$7 -> 0.72746955 | F8: =IFERROR(D8/C8, "-") -> 1.5272727
A9: 2 | B9: Россия | C9: 275 | D9: 417 | E9: =D9/$D$7 -> 0.11285521 | F9: =IFERROR(D9/C9, "-") -> 1.5163636
A10: 3 | B10: АҚШ | C10: 45 | D10: 72 | E10: =D10/$D$7 -> 0.019485792 | F10: =IFERROR(D10/C10, "-") -> 1.6
A11: 4 | B11: Қозоғистон | C11: 32 | D11: 63 | E11: =D11/$D$7 -> 0.017050068 | F11: =IFERROR(D11/C11, "-") -> 1.96875
A12: 5 | B12: Беларус | C12: 36 | D12: 50 | E12: =D12/$D$7 -> 0.0135318 | F12: =IFERROR(D12/C12, "-") -> 1.3888889
A13: 6 | B13: Буюк Британия | C13: 17 | D13: 27 | E13: =D13/$D$7 -> 0.0073071719 | F13: =IFERROR(D13/C13, "-") -> 1.5882353
A14: 7 | B14: Япония | C14: 9 | D14: 26 | E14: =D14/$D$7 -> 0.0070365359 | F14: =IFERROR(D14/C14, "-") -> 2.8888889
A15: 8 | B15: Жанубий Корея | C15: 18 | D15: 25 | E15: =D15/$D$7 -> 0.0067658999 | F15: =IFERROR(D15/C15, "-") -> 1.3888889
A16: 9 | B16: Тожикистон | C16: 12 | D16: 22 | E16: =D16/$D$7 -> 0.0059539919 | F16: =IFERROR(D16/C16, "-") -> 1.8333333
A17: 10 | B17: Туркия | C17: 3 | D17: 21 | E17: =D17/$D$7 -> 0.0056833559 | F17: =IFERROR(D17/C17, "-") -> 7
A18: 11 | B18: Исроил | C18: 15 | D18: 18 | E18: =D18/$D$7 -> 0.0048714479 | F18: =IFERROR(D18/C18, "-") -> 1.2
A19: 12 | B19: Қирғизистон | C19: 9 | D19: 18 | E19: =D19/$D$7 -> 0.0048714479 | F19: =IFERROR(D19/C19, "-") -> 2
... A74: 67 | B74: Шветсия | C74: 1 | D74: 1 | E74: =D74/$D$7 -> 0.00027063599 | F74: =IFERROR(D74/C74, "-") -> 1

Sheet 8-жадвал
F1: 8-жадвал
A3: Тақдим этилган хизматлар хақида маълумот (Ягона дарча /OSS/)
F4: бирлик
A5: № | B5: Кўрсаткич номи | C5: ='2-жадвал'!C5 -> 2024-йил | D5: ='2-жадвал'!D5 -> 2025-йил | E5: Улуши | F5: Ўсиш суръати
A7: 1 | B7: OSS дастури доирасида кўрсатилган рўйхатдан ўтказиш хизматларининг сони - жами | C7: 123 | D7: 137 | E7: =E9+E10 -> 1 | F7: =IFERROR(D7/C7, "-") -> 1.1138211
B8: шундан:
A9: 1.1 | B9: IT-Park резиденти сифатида рўйхатдан ўтиш | C9: 96 | D9: 113 | E9: =D9/$D$7 -> 0.82481752 | F9: =IFERROR(D9/C9, "-") -> 1.1770833
A10: 1.2 | B10: Бошқа йўналишлар бўйича рўйхатдан ўтиш | C10: 27 | D10: 24 | E10: =D10/$D$7 -> 0.17518248 | F10: =IFERROR(D10/C10, "-") -> 0.88888889
A11: 2 | B11: IT-Park резидентлигидан махрум қилинди (OSS) | C11: 3 | D11: 28 | E11: =D11/$D$7 -> 0.20437956 | F11: =IFERROR(D11/C11, "-") -> 9.3333333
A13: Мурожаатлар хақида маълумот
F14: бирлик
A15: № | B15: Кўрсаткич номи | C15: ='2-жадвал'!C5 -> 2024-йил | D15: ='2-жадвал'!D5 -> 2025-йил | E15: Улуши | F15: Ўсиш суръати
A17: 1 | B17: Қабул қилинган сўровларнинг умумий сони | C17: =SUM(C19:C24) -> 276 | D17: =SUM(D19:D24) -> 789 | E17: =SUM(E18:E24) -> 1 | F17: =IFERROR(D17/C17, "-") -> 2.8586957
B18: шундан мурожаат тури бўйича:
A19: 1.1 | B19: Солиқ масалалари | C19: 183 | D19: 364 | E19: =D19/$D$17 -> 0.46134347 | F19: =IFERROR(D19/C19, "-") -> 1.989071
A20: 1.2 | B20: Банк иши | C20: 48 | D20: 267 | E20: =D20/$D$17 -> 0.33840304 | F20: =IFERROR(D20/C20, "-") -> 5.5625
A21: 1.3 | B21: Мехнат ресурслари бўйича | C21: 11 | D21: 58 | E21: =D21/$D$17 -> 0.073510773 | F21: =IFERROR(D21/C21, "-") -> 5.2727273
A22: 1.4 | B22: Хуқуқий | C22: 10 | D22: 38 | E22: =D22/$D$17 -> 0.048162231 | F22: =IFERROR(D22/C22, "-") -> 3.8
A23: 1.5 | B23: Инфратузилма | C23: 8 | D23: 18 | E23: =D23/$D$17 -> 0.022813688 | F23: =IFERROR(D23/C23, "-") -> 2.25
A24: 1.6 | B24: Бошқалар | C24: 16 | D24: 44 | E24: =D24/$D$17 -> 0.055766793 | F24: =IFERROR(D24/C24, "-") -> 2.75

Sheet 8.1-жадвал
F1: 8.1-жадвал
A2: 2025 йил учун мамлакатлар кесимида Ягона дарча (One Stop Shop / OSS) орқали кўрсатилган хизматлар тўғрисида маълумот
F3: бирлик
A4: № | B4: Мамлакат | C4: Жами (OSS) | D4: шундан: | F4: Улуши
D5: IT-Park резиденти сифатида | E5: Резидентлик-дан махрум қилинган
B7: Жами | C7: =D7+E7 -> 137 | D7: =SUM(D8:D217) -> 113 | E7: =SUM(E8:E217) -> 24 | F7: =SUM(F8:F41) -> 1
A8: 1 | B8: Россия | C8: =D8+E8 -> 38 | D8: 33 | E8: 5 | F8: =C8/$C$7 -> 0.27737226
A9: 2 | B9: Озарбайжон | C9: =D9+E9 -> 8 | D9: 4 | E9: 4 | F9: =C9/$C$7 -> 0.058394161
A10: 3 | B10: Қозоғистон | C10: =D10+E10 -> 8 | D10: 6 | E10: 2 | F10: =C10/$C$7 -> 0.058394161
A11: 4 | B11: Япония | C11: =D11+E11 -> 8 | D11: 6 | E11: 2 | F11: =C11/$C$7 -> 0.058394161
A12: 5 | B12: Ҳиндистон | C12: =D12+E12 -> 7 | D12: 6 | E12: 1 | F12: =C12/$C$7 -> 0.051094891
A13: 6 | B13: Туркия | C13: =D13+E13 -> 7 | D13: 7 | E13: 0 | F13: =C13/$C$7 -> 0.051094891
A14: 7 | B14: Беларус | C14: =D14+E14 -> 6 | D14: 6 | E14: 0 | F14: =C14/$C$7 -> 0.04379562
A15: 8 | B15: АҚШ | C15: =D15+E15 -> 6 | D15: 5 | E15: 1 | F15: =C15/$C$7 -> 0.04379562
A16: 9 | B16: Хитой | C16: =D16+E16 -> 4 | D16: 4 | E16: 0 | F16: =C16/$C$7 -> 0.02919708
A17: 10 | B17: Уммон | C17: =D17+E17 -> 4 | D17: 3 | E17: 1 | F17: =C17/$C$7 -> 0.02919708
A18: 11 | B18: Покистон | C18: =D18+E18 -> 4 | D18: 4 | E18: 0 | F18: =C18/$C$7 -> 0.02919708
A19: 12 | B19: Жанубий Корея | C19: =D19+E19 -> 4 | D19: 4 | E19: 0 | F19: =C19/$C$7 -> 0.02919708
... A41: 34 | B41: Франсия | C41: =D41+E41 -> 1 | D41: 1 | E41: 0 | F41: =C41/$C$7 -> 0.0072992701

Sheet 9-жадвал
F1: 9-жадвал
A3: IT Visa дастури бўйича берилган IT Cardлар тўғрисида маълумот
F4: бирлик
A5: № | B5: Кўрсаткич номи | C5: ='2-жадвал'!C5 -> 2024-йил | D5: ='2-жадвал'!D5 -> 2025-йил | E5: Улуши | F5: Ўсиш суръати
A7: 1 | B7: Хисобот даврида берилган IT-карталар | C7: =C9+C10+C11 -> 233 | D7: =D9+D10+D11 -> 315 | E7: =E9+E10+E11 -> 1 | F7: =IFERROR(D7/C7, "-") -> 1.3519313
B8: шундан:
A9: 1.1 | B9: компания асосчиларига | C9: 96 | D9: 128 | E9: =D9/$D$7 -> 0.40634921 | F9: =IFERROR(D9/C9, "-") -> 1.3333333
A10: 1.2 | B10: инвесторларга | C10: 9 | D10: 7 | E10: =D10/$D$7 -> 0.022222222 | F10: =IFERROR(D10/C10, "-") -> 0.77777778
A11: 1.3 | B11: IT мутахассисларига | C11: 128 | D11: 180 | E11: =D11/$D$7 -> 0.57142857 | F11: =IFERROR(D11/C11, "-") -> 1.40625
A12: 2 | B12: Берилган IT-карталар жами (2022-йилдан бошлаб) | C12: 733 | D12: 1048 | E12: X | F12: =IFERROR(D12/C12, "-") -> 1.4297408

Sheet 9.1-жадвал
L1: 9.1-жадвал
A2: Мамлакатлар кесимида берилган IT-карталар хақида маълумот
L3: бирлик
A4: № | B4: Мамлакат | C4: Хисобот даврида берилган IT-карталар сони | H4: Берилган IT-карталар жами (ўсиб бориш тартибида)
C5: компания асосчиларига | D5: инвестор-ларга | E5: IT мутахас-сисларга | F5: Жами | G5: Улуши | H5: компания асосчиларига | I5: инвестор-ларга | J5: IT мутахас-сисларга | K5: Жами | L5: Улуши
B7: Жами | C7: =SUM(C8:C249) -> 128 | D7: =SUM(D8:D249) -> 7 | E7: =SUM(E8:E249) -> 180 | F7: =SUM(F8:F249) -> 315 | G7: =SUM(G8:G249) -> 1 | H7: =SUM(H8:H249) -> 366 | I7: =SUM(I8:I249) -> 20 | J7: =SUM(J8:J249) -> 662 | ... L7: =SUM(L8:L249) -> 1
A8: 1 | B8: Россия Федерацияси | C8: 43 | D8: 2 | E8: 114 | F8: =SUM(C8:E8) -> 159 | G8: =F8/$F$7 -> 0.5047619 | H8: 179 | I8: 6 | J8: 484 | K8: =SUM(H8:J8) -> 669 | L8: =K8/$K$7 -> 0.63835878
A9: 2 | B9: Тожикистон | C9: 13 | D9: 2 | E9: 21 | F9: =SUM(C9:E9) -> 36 | G9: =F9/$F$7 -> 0.11428571 | H9: 24 | I9: 4 | J9: 38 | K9: =SUM(H9:J9) -> 66 | L9: =K9/$K$7 -> 0.062977099
A10: 3 | B10: Беларусь | C10: 1 | D10: 0 | E10: 16 | F10: =SUM(C10:E10) -> 17 | G10: =F10/$F$7 -> 0.053968254 | H10: 10 | I10: 0 | J10: 67 | K10: =SUM(H10:J10) -> 77 | L10: =K10/$K$7 -> 0.073473282
A11: 4 | B11: Қозоғистон | C11: 3 | D11: 0 | E11: 12 | F11: =SUM(C11:E11) -> 15 | G11: =F11/$F$7 -> 0.047619048 | H11: 8 | I11: 1 | J11: 23 | K11: =SUM(H11:J11) -> 32 | L11: =K11/$K$7 -> 0.030534351
A12: 5 | B12: Қирғизистон | C12: 7 | D12: 0 | E12: 5 | F12: =SUM(C12:E12) -> 12 | G12: =F12/$F$7 -> 0.038095238 | H12: 14 | I12: 0 | J12: 10 | K12: =SUM(H12:J12) -> 24 | L12: =K12/$K$7 -> 0.022900763
A13: 6 | B13: Эрон | C13: 9 | D13: 2 | E13: 0 | F13: =SUM(C13:E13) -> 11 | G13: =F13/$F$7 -> 0.034920635 | H13: 13 | I13: 2 | J13: 0 | K13: =SUM(H13:J13) -> 15 | L13: =K13/$K$7 -> 0.014312977
A14: 7 | B14: Жанубий Корея | C14: 5 | D14: 0 | E14: 4 | F14: =SUM(C14:E14) -> 9 | G14: =F14/$F$7 -> 0.028571429 | H14: 12 | I14: 1 | J14: 7 | K14: =SUM(H14:J14) -> 20 | L14: =K14/$K$7 -> 0.019083969
A15: 8 | B15: Покистон | C15: 8 | D15: 0 | E15: 0 | F15: =SUM(C15:E15) -> 8 | G15: =F15/$F$7 -> 0.025396825 | H15: 11 | I15: 0 | J15: 0 | K15: =SUM(H15:J15) -> 11 | L15: =K15/$K$7 -> 0.010496183
A16: 9 | B16: Япония | C16: 7 | D16: 0 | E16: 0 | F16: =SUM(C16:E16) -> 7 | G16: =F16/$F$7 -> 0.022222222 | H16: 9 | I16: 0 | J16: 1 | K16: =SUM(H16:J16) -> 10 | L16: =K16/$K$7 -> 0.0095419847
A17: 10 | B17: АҚШ | C17: 3 | D17: 0 | E17: 1 | F17: =SUM(C17:E17) -> 4 | G17: =F17/$F$7 -> 0.012698413 | H17: 14 | I17: 1 | J17: 1 | K17: =SUM(H17:J17) -> 16 | L17: =K17/$K$7 -> 0.015267176
A18: 11 | B18: Хитой | C18: 3 | D18: 0 | E18: 1 | F18: =SUM(C18:E18) -> 4 | G18: =F18/$F$7 -> 0.012698413 | H18: 10 | I18: 0 | J18: 1 | K18: =SUM(H18:J18) -> 11 | L18: =K18/$K$7 -> 0.010496183
A19: 12 | B19: Туркия | C19: 3 | D19: 0 | E19: 1 | F19: =SUM(C19:E19) -> 4 | G19: =F19/$F$7 -> 0.012698413 | H19: 5 | I19: 0 | J19: 3 | K19: =SUM(H19:J19) -> 8 | L19: =K19/$K$7 -> 0.0076335878
... A55: 48 | B55: Бангладеш | C55: 0 | D55: 0 | E55: 0 | F55: =SUM(C55:E55) -> 0 | G55: =F55/$F$7 -> 0 | H55: 0 | I55: 0 | J55: 1 | K55: =SUM(H55:J55) -> 1 | L55: =K55/$K$7 -> 0.00095419847

Sheet 10-жадвал
G1: 10-жадвал
A3: IT Park хорижий резидентлари (асосий кўрсаткичлар)
A5: № | B5: Кўрсаткич номи | C5: ='2-жадвал'!C5 -> 2024-йил | D5: ='2-жадвал'!D5 -> 2025-йил | E5: Хорижий улуш | F5: IT park улуши | G5: Ўсиш суръати
A7: 1 | B7: Жами даромад, млрд. сўм | C7: 7407.9 | D7: 11839 | E7: 1 | F7: 1 | G7: =IFERROR(D7/C7, "-") -> 1.5981587
B8: шундан:
A9: 1.1 | B9: Ички бозор, млрд. сўм | C9: 3780.95 | D9: 6513.3 | E9: 0.26483289 | F9: 0.73516711 | G9: =IFERROR(D9/C9, "-") -> 1.7226623
A10: 1.2 | B10: ИТ хизматлари экспорти, млрд. сўм | C10: 3626.95 | D10: 5325.7 | E10: 0.60443763 | F10: 0.39556237 | G10: =IFERROR(D10/C10, "-") -> 1.4683687
A11: 2 | B11: ИТ хизматлари экспорти, млн. АҚШ долл. | C11: 273.85 | D11: 409.21 | E11: 0.57280235 | F11: 0.42719765 | G11: =IFERROR(D11/C11, "-") -> 1.4942852
A12: 3 | B12: Инвеститсиялар, млн. АҚШ долл. | G12: =IFERROR(D12/C12, "-") -> -
A13: 3.1 | B13: шу жумладан, тўғридан-тўғри хорижий инвеститсиялар | G13: =IFERROR(D13/C13, "-") -> -
A14: 4 | B14: Резидентлар сони | C14: 619 | D14: 972 | E14: х | F14: х | G14: =IFERROR(D14/C14, "-") -> 1.5702746
A15: 5 | B15: Фаолиятини давом эттираётган резидентлар улуши (%) | C15: 515 | D15: 949 | E15: х | F15: х | G15: =IFERROR(D15/C15, "-") -> 1.8427184
A16: 5.1 | B16: 1 йилдан кам, % | C16: 13 | D16: 469 | E16: х | F16: х | G16: =IFERROR(D16/C16, "-") -> 36.076923
A17: 5.2 | B17: 3 йилдан ортиқ, % | C17: 169 | D17: 155 | E17: х | F17: х | G17: =IFERROR(D17/C17, "-") -> 0.91715976
A18: 6 | B18: Резидентлар ходимлари сони | C18: 10488 | D18: 14796 | E18: х | F18: х | G18: =IFERROR(D18/C18, "-") -> 1.4107551
A19: 7 | B19: Тақдим этилган мамлакатлар сони | C19: 46 | D19: 49 | E19: х | F19: х | G19: =IFERROR(D19/C19, "-") -> 1.0652174

Sheet 11-жадвал
E1: 11-жадвал
A3: Халқаро ҳамкорликлар ва IT-Park тадбирлари
E4: бирлик
A5: № | B5: Кўрсаткич номи | C5: ='2-жадвал'!C5 -> 2024-йил | D5: ='2-жадвал'!D5 -> 2025-йил | E5: Изоҳ / натижа
A7: 1 | B7: Халқаро келишувлар сони, (меморандум) | C7: 21 | D7: 71 | E7: технопарклар, акселераторлар,…
A8: 1.1 | B8: Келишув ва ўзаро англашув меморандумлари имзоланган мамлакатлар сони | C8: 14 | D8: 24 | E8: Жанубий Карея, Япония, БАА…
A9: 2 | B9: IT-Park қабул қилган давлат ташрифлари | C9: 32 | D9: 128 | E9: АҚШ, Канада…
A10: 3 | B10: Ўзбекистоннинг хорижга давлат делегациялари | C10: -- | D10: 31 | E10: Хитой, Япония, АҚШ,…
A11: 4 | B11: Янги ҳамкорликлар | C11: -- | D11: 45 | E11: Сингапур, Россия…
A12: 5 | B12: IT-Park томонидан виза кўмаги | C12: 81 | D12: 77 | E12: БАА, Уммон
A13: 5.1 | B13: хорижий меҳмонлар учун | C13: 51 | D13: 37 | E13: Хиндистон, Саудия Арабистони
A14: 5.2 | B14: IT-Park раҳбарияти ва ходимлари учун | C14: 30 | D14: 40 | E14: АҚШ, Австралия…
A15: 6 | B15: KOICA билан лойиҳа (Тайёрланган мутахассислар умумий сони) | C15: 40 | D15: 30
A16: 7 | B16: Ўзбек–Корея BPO Форуми (Иштирокчилар сони) | C16: 140 | D16: 150+
A17: 7.1 | B17: Ўзбек–Корея BPO Форуми доирасида ишга туширилган пилот лойиҳалар | C17: -- | D17: 3
A18: 7.2 | B18: Ўзбек–Корея BPO Форуми доирасида имзоланган меморандумлар | C18: 3 | D18: 9
A19: 7.3 | B19: Ўзбек–Корея BPO Форуми доирасида уюштирилган B2B учрашувлар | C19: -- | D19: 23
A20: 8 | B20: «Bonus system» лойиҳаси доирасидаги амалдаги шартномалар сони | C20: -- | D20: 23

Sheet KPI
B2: 2025 йил якунлари ҳамда 2026 йил учун KPI кўрсаткичлари асосида вилоятлар кесимида хизматлар ҳажми, экспорт кўрсаткичлари ва ходимлар сони тўғрисида МАЪЛУМОТ
B4: Худудлар | D4: Резидентлар сони | G4: Ётоқхонада яшовчи фрилансерлар сони | J4: Таълим йўналишидаги резидентлар сони | M4: Сунъий интеллект йўналишидаги резидентлар сони | P4: Экспорт қилувчи резидентлар сони | S4: Экспорт ҳажми (минг АҚШ доллари) | V4: Хизматлар жами (млрд сўм) | Y4: Ходимлар сони
D5: 2025 амалда | E5: 2026 KPI | F5: Ўзгариши | G5: 2025 амалда | H5: 2026 KPI | I5: Ўзгариши | J5: 2025 амалда | K5: 2026 KPI | L5: Ўзгариши | M5: 2025 амалда | N5: 2026 KPI | O5: Ўзгариши | P5: 2025 амалда | Q5: 2026 KPI | R5: Ўзгариши | S5: 2025 амалда | T5: 2026 KPI | U5: Ўзгариши | V5: 2025 амалда | W5: 2026 KPI | X5: Ўзгариши | Y5: 2025 амалда | Z5: 2026 KPI | AA5: Ўзгариши
